Error in sys.excepthook:
Traceback (most recent call last):
  File "C:\ProgramData\Anaconda3\lib\site-packages\wandb\sdk\wandb_run.py", line 147, in exc_handler
    traceback.print_exception(exc_type, exc, tb)
  File "C:\ProgramData\Anaconda3\lib\traceback.py", line 105, in print_exception
    print(line, file=file, end="")
TypeError: info() got an unexpected keyword argument 'file'
Original exception was:
Traceback (most recent call last):
  File "SmallTrainSize.py", line 329, in <module>
    print(f'exp: {experiment_count}, running on {device}')
NameError: name 'experiment_count' is not defined