
DEEPMLO PiNet 0
tensor([[    0,     0,     1,  ..., 10122, 10123, 10124],
        [    1,     2,     3,  ..., 10123, 10124, 10125]])
tensor([[    0,     0,     1,  ..., 10122, 10123, 10124],
        [    1,     2,     3,  ..., 10123, 10124, 10125]])
Error in sys.excepthook:
Traceback (most recent call last):
  File "C:\ProgramData\Anaconda3\lib\site-packages\wandb\sdk\wandb_run.py", line 147, in exc_handler
    traceback.print_exception(exc_type, exc, tb)
  File "C:\ProgramData\Anaconda3\lib\traceback.py", line 105, in print_exception
    print(line, file=file, end="")
TypeError: info() got an unexpected keyword argument 'file'
Original exception was:
Traceback (most recent call last):
  File "SmallTrainSize.py", line 371, in <module>
    train_acc, precision_1_train, recall_1_train,precision_0_train, recall_0_train, f1_0_train, f1_1_train = evaluate(train_loader)
  File "SmallTrainSize.py", line 271, in evaluate
    tn, fp, fn, tp = metrics.confusion_matrix(label, pred).ravel()
  File "C:\ProgramData\Anaconda3\lib\site-packages\sklearn\utils\validation.py", line 72, in inner_f
    return f(**kwargs)
  File "C:\ProgramData\Anaconda3\lib\site-packages\sklearn\metrics\_classification.py", line 276, in confusion_matrix
    y_type, y_true, y_pred = _check_targets(y_true, y_pred)
  File "C:\ProgramData\Anaconda3\lib\site-packages\sklearn\metrics\_classification.py", line 90, in _check_targets
    raise ValueError("Classification metrics can't handle a mix of {0} "
ValueError: Classification metrics can't handle a mix of binary and continuous-multioutput targets