
DEEPMLO PiNet
tensor([[   0,    0,    1,  ..., 9215, 9216, 9217],
        [   1,    2,    3,  ..., 9216, 9217, 9218]])
tensor([[   0,    0,    1,  ..., 8980, 8981, 8982],
        [   1,    2,    3,  ..., 8981, 8982, 8983]])
Error in sys.excepthook:
Traceback (most recent call last):
  File "C:\ProgramData\Anaconda3\lib\site-packages\wandb\sdk\wandb_run.py", line 147, in exc_handler
    traceback.print_exception(exc_type, exc, tb)
  File "C:\ProgramData\Anaconda3\lib\traceback.py", line 105, in print_exception
    print(line, file=file, end="")
TypeError: info() got an unexpected keyword argument 'file'
Original exception was:
Traceback (most recent call last):
  File "ImprovedPiNet.py", line 481, in <module>
    train_acc, precision_1_train, recall_1_train,precision_0_train, recall_0_train, f1_0_train, f1_1_train = evaluate(train_loader)
  File "ImprovedPiNet.py", line 332, in evaluate
    tn, fp, fn, tp = metrics.confusion_matrix(np.array(data.y), np.array(pred), labels=[0, 1]).ravel()
  File "C:\ProgramData\Anaconda3\lib\site-packages\sklearn\utils\validation.py", line 72, in inner_f
    return f(**kwargs)
  File "C:\ProgramData\Anaconda3\lib\site-packages\sklearn\metrics\_classification.py", line 276, in confusion_matrix
    y_type, y_true, y_pred = _check_targets(y_true, y_pred)
  File "C:\ProgramData\Anaconda3\lib\site-packages\sklearn\metrics\_classification.py", line 90, in _check_targets
    raise ValueError("Classification metrics can't handle a mix of {0} "
ValueError: Classification metrics can't handle a mix of binary and continuous-multioutput targets